<?xml version="1.0"?>
<robot xmlns:xacro="https://www.ros.org/wiki/xacro">

    <xacro:include filename="inertial_macros.xacro"/>

    <material name="White">
        <color rgba="1 1 1 1"/>
    </material>

    <material name="Black">
        <color rgba="0 0 0 1"/>
    </material>

    <!-- base link -->
    
    <link name="base_link">

    </link>
    
    <!-- base footprint -->
    
    <joint name="base_footprint_joint" type="fixed">
        <parent link="base_link"/>
        <child link="base_footprint"/>
        <origin xyz="0 0 0" rpy="0 0 0"/> 
    </joint>
    
    <link name="base_footprint">
    
    </link>

    <!-- chassis -->

    <joint name="chassis_joint" type="fixed">
        <parent link="base_link"/>
        <child link="chassis_link"/>
        <origin xyz="-0.2 0 0"/> <!-- chassis_link at the back of the box --> <!-- origin is described w.r.t. the parent link -->
    </joint>

    <link name="chassis_link">
        <visual>
            <origin xyz="0.2 0 0.075"/> <!--shift the box foward by half its length and up by half its length for the origin of chasssis_link to be in the back of the base_link -->
            <geometry>
                <box size="0.4 0.3 0.15"/>  <!-- the model spawns around the chassis_link as its center -->
            </geometry>
            <material name="White"/>
        </visual>
        <collision>
            <origin xyz="0.2 0 0.075"/>
            <geometry>
                <box size="0.4 0.3 0.15"/>
            </geometry>
        </collision>
        <xacro:inertial_box mass="0.6" x="0.4" y="0.3" z="0.15">
            <origin xyz="0.2 0 0.075" rpy="0 0 0"/>
        </xacro:inertial_box>
    </link>

    <gazebo reference="chassis_link">
        <material>Gazebo/White</material>
    </gazebo>

    
    <!-- wheels -->
      
    <!-- left rear wheel -->
    <joint name="left_rear_joint" type="continuous">
        <parent link="base_link"/>
        <child link="left_rear_link"/>
        <origin xyz="-0.1 0.1625 0" rpy="-${pi/2} 0 0"/> <!-- cylinders ae oriented along z axis by default so we need to rotate them 90 degrees counterclockwise in the x axis -->
        <axis xyz="0 0 1"/>                             <!-- axis of rotation-->
    </joint>

    <link name="left_rear_link">
        <visual>
            <origin xyz="0 0 0"/>
            <geometry>
                <cylinder radius="0.05" length="0.025"/>
            </geometry>
            <material name="Black"/>
        </visual>
        <collision>
            <origin xyz="0 0 0"/>
            <geometry>
                <cylinder radius="0.05" length="0.025"/>
            </geometry>
        </collision>
        <xacro:inertial_cylinder mass="0.1" length="0.025" radius="0.05">
            <origin xyz="0 0 0" rpy="0 0 0"/>
        </xacro:inertial_cylinder>
    </link>

    <gazebo reference="left_rear_link">
        <material>Gazebo/Black</material>
    </gazebo>
    
    <!-- right rear wheel -->
    <joint name="right_rear_joint" type="continuous">
        <parent link="base_link"/>
        <child link="right_rear_link"/>
        <origin xyz="-0.1 -0.1625 0" rpy="${pi/2} 0 0"/>
        <axis xyz="0 0 -1"/>
    </joint>

    <link name="right_rear_link">
        <visual>
            <origin xyz="0 0 0"/>
            <geometry>
                <cylinder radius="0.05" length="0.025"/>
            </geometry>
            <material name="Black"/>
        </visual>
        <collision>
            <origin xyz="0 0 0"/>
            <geometry>
                <cylinder radius="0.05" length="0.025"/>
            </geometry>
        </collision>
        <xacro:inertial_cylinder mass="0.1" length="0.025" radius="0.05">
            <origin xyz="0 0 0" rpy="0 0 0"/>
        </xacro:inertial_cylinder>
    </link>

    <gazebo reference="right_rear_link">
        <material>Gazebo/Black</material>
    </gazebo>

    <!-- caster wheel -->
    <joint name="caster_wheel_joint" type="fixed">
        <parent link="base_link"/>
        <child link="caster_link"/>
        <origin xyz="0.15 0 0" rpy="0 0 0"/>
    </joint>

    <link name="caster_link">
        <visual>
            <origin xyz="0 0 0"/>
            <geometry>
                <sphere radius="0.05"/>
            </geometry>
            <material name="Black"/>
        </visual>
        <collision>
            <origin xyz="0 0 0"/>
            <geometry>
                <sphere radius="0.05"/>
            </geometry>
        </collision>
        <xacro:inertial_sphere mass="0.1" radius="0.05">
            <origin xyz="0 0 0" rpy="0 0 0"/>
        </xacro:inertial_sphere>
    </link>

    <gazebo reference="caster_link">
        <material>Gazebo/Black</material>
        <mu1 value="0.001"/>
        <mu2 value="0.001"/>
    </gazebo>

</robot>
